<?xml version="1.0" ?>
<robot name="actuated_platform">
  
  <material name="white">
	<color rgba="0.95 0.95 0.95 1"/>
  </material>
  
  <material name="silver">
	<color rgba="0.3 0.3 0.3 1"/>
  </material>

  <link name="world" />

  <joint name="world_joint" type="fixed">
    <origin rpy="0 0 -3.14159265359" xyz="0 0 0"/>
    <parent link="world"/>
    <child link="actuated_platform/base"/>
  </joint>
  
  <link name="actuated_platform/base">
	<visual>
		<origin xyz="0 0 0"/>
		<geometry>
			<mesh filename="../Data/meshes/PlatformBase.stl" scale="0.001 0.001 0.001"/>
		</geometry>
		<material name="silver"/>
	</visual>
	
	<collision>
		<origin xyz="0 0 0"/>
		<geometry>
			<mesh filename="../Data/meshes/PlatformBase.stl" scale="0.001 0.001 0.001"/>
		</geometry>
	</collision>
	
	<inertial>
      <origin rpy="0 0 0" xyz="0 0 0"/>
      <mass value="20"/>
      <inertia ixx="0.0033530000" ixy="-0.0001246000" ixz="0.0000110600" iyy="0.0013570000" iyz="0.0002103000" izz="0.0041110000"/>
    </inertial>
  </link>
  
  <joint name="base_mount_joint" type="revolute">
    <parent link="actuated_platform/base"/>
    <child link="actuated_platform/plate"/>
    <axis xyz="0 0 1"/>
    <limit effort="1" lower="-9999999999" upper="9999999999" velocity="5"/>
    <origin xyz="0 0 0"/>
  </joint>
  
  <link name="actuated_platform/plate">
	<visual>
		<origin xyz="0 0 0"/>
		<geometry>
			<mesh filename="../Data/meshes/PlatformPlate.stl" scale="0.001 0.001 0.001"/>
		</geometry>
		<material name="white"/>
	</visual>
	
	<collision>
		<origin xyz="0 0 0"/>
		<geometry>
			<mesh filename="../Data/meshes/PlatformPlate.stl" scale="0.001 0.001 0.001"/>
		</geometry>
	</collision>
	
	<inertial>
      <origin rpy="0 0 0" xyz="0 0 0"/>
      <mass value="1"/>
      <inertia ixx="0.0033530000" ixy="-0.0001246000" ixz="0.0000110600" iyy="0.0013570000" iyz="0.0002103000" izz="0.0041110000"/>
    </inertial>
  </link>

  <link name="actuated_platform/object">
  	<visual>
		<origin xyz="0 0 0"/>
		<geometry>
			<mesh filename="../Data/models/Cylinder.obj" scale="1 1 1"/>
		</geometry>
		<material name="white"/>
	</visual>

	<collision>
		<origin xyz="0 0 0"/>
		<geometry>
			<mesh filename="../Data/models/Cylinder.obj" scale="1 1 1"/>
		</geometry>
	</collision>

	<inertial>
      <origin rpy="0 0 0" xyz="0 0 0"/>
      <mass value="1"/>
      <inertia ixx="0.0033530000" ixy="-0.0001246000" ixz="0.0000110600" iyy="0.0013570000" iyz="0.0002103000" izz="0.0041110000"/>
    </inertial>
  </link>

  <joint name="obj_fixed" type="fixed">
    <parent link="actuated_platform/plate"/>
    <child link="actuated_platform/object"/>
    <origin xyz="0 0 0.16"/>
  </joint>


</robot>
