<?xml version="1.0" ?>
<robot name="rot_base">
  <material name="object_color">
	<color rgba="1 1 1 1"/>
  </material>
  
  <material name="black">
	<color rgba="0 0 0 1"/>
  </material>
  
  <link name="rot_base/base">
	<visual>
		<origin xyz="0 0 0"/>
		<geometry>
			<box size="0.0381 0.0381 0.127"/>
		</geometry>
		<material name="black"/>
	</visual>
	
	<collision>
		<origin xyz="0 0 0"/>
		<geometry>
			<box size="0.0381 0.0381 0.127"/>
		</geometry>
	</collision>
	
	<inertial>
      <origin rpy="0 0 0" xyz="0 0 0"/>
      <mass value="0"/>
      <inertia ixx="0" ixy="0" ixz="0" iyy="0" iyz="0" izz="0"/>
    </inertial>
  </link>
  
  <joint name="base_mount_joint" type="revolute">
    <parent link="rot_base/base"/>
    <child link="rot_base/plate"/>
    <axis xyz="0 0 1"/>
    <limit effort="0" lower="-3.14159265359" upper="3.14159265359" velocity="10"/>
    <origin xyz="0 0 0.07699375"/>
  </joint>
  
  <link name="rot_base/plate">
	<visual>
		<origin xyz="0 0 0"/>
		<geometry>
			<cylinder length="0.0269875" radius="0.1016"/>
		</geometry>
		<material name="white"/>
	</visual>
	
	<collision>
		<origin xyz="0 0 0"/>
		<geometry>
			<cylinder length="0.0269875" radius="0.1016"/>
		</geometry>
	</collision>
	
	<inertial>
      <origin rpy="0 0 1.5707963267948966" xyz="-0.0354389000 -0.0033586100 0.0253408000"/>
      <mass value="1"/>
      <inertia ixx="0.0033530000" ixy="-0.0001246000" ixz="0.0000110600" iyy="0.0013570000" iyz="0.0002103000" izz="0.0041110000"/>
    </inertial>
  </link>
  
  <joint name="object_plate_joint" type="fixed">
    <parent link="rot_base/plate"/>
    <child link="rot_base/object"/>
    <origin xyz="0.003 0.006 0.01349375"/>
  </joint>
  
  <link name="rot_base/object">
    <visual>
      <origin rpy="0 0 1.5707963267948966" xyz="0 0 0"/>
      <geometry>
        <mesh filename="package://data/sim/meshes/object_exp.stl" scale="0.001 0.001 0.001"/>
      </geometry>
      <material name="object_color"/>
    </visual>
	
    <collision>
      <origin rpy="0 0 1.5707963267948966" xyz="0 0 0"/>
      <geometry>
        <mesh filename="package://data/sim/meshes/object_exp.stl" scale="0.001 0.001 0.001"/>
      </geometry>
    </collision>
	
    <inertial>
      <origin rpy="0 0 0" xyz="0 0 0"/>
      <mass value="0.05"/>
      <inertia ixx="0.0" ixy="0.0" ixz="0.0" iyy="0.0" iyz="0.0" izz="0.0"/>
    </inertial>
  </link>
  
</robot>
