<?xml version="1.0" ?>
<!-- =================================================================================== -->
<!-- |    This document was autogenerated by xacro from rx200pantex.urdf.xacro         | -->
<!-- |    EDITING THIS FILE BY HAND IS NOT RECOMMENDED                                 | -->
<!-- =================================================================================== -->
<robot name="rx200pantex">
  <material name="interbotix_black">
    <texture filename="package://data/sim/meshes/interbotix_black.png"/>
  </material>
  
  <material name="white">
	<color rgba="1 1 1 1"/>
  </material>
  
  <material name="blue">
	<color rgba="0 0 0.8 1"/>
  </material>
  
<!-- Linear actuator 9/29 -->
  
  <!-- body of the linear actuator that is mounted to the chamber. -->
  <link name="rx200pantex/base">
	<visual>
		<origin xyz="0 0 0"/>
		<geometry>
			<box size="0.14605 0.428625 0.066675"/>
		</geometry>
		<material name="blue"/>
	</visual>
	
	<collision>
		<origin xyz="0 0 0"/>
		<geometry>
			<box size="0.14605 0.428625 0.066675"/>
		</geometry>
	</collision>
	
	<inertial>
      <origin rpy="0 0 0" xyz="0 0 0"/>
      <mass value="0"/>
      <inertia ixx="0" ixy="0" ixz="0" iyy="0" iyz="0" izz="0"/>
    </inertial>
  </link>
  
  <!-- prismatic joint that connects base to mount. Linear (y) motion. -->
  <joint name="base_mount_joint" type="prismatic">
    <parent link="rx200pantex/base"/>
    <child link="rx200pantex/mount"/>
    <axis xyz="0 1 0"/>
    <limit effort="1000" lower="0" upper="0.270" velocity="1"/>
    <origin xyz="0 -0.13625625 0.0418375"/>
  </joint>
 
  <!-- mount plate that the RX200 rests upon -->
   <link name="rx200pantex/mount">
	<visual>
		<origin xyz="0 0 0"/>
		<geometry>
			<box size="0.1651 0.1524 0.007"/>
		</geometry>
		<material name="white"/>
	</visual>
	
	<collision>
		<origin xyz="0 0 0"/>
		<geometry>
			<box size="0.1651 0.1524 0.007"/>
		</geometry>
	</collision>
	
	<inertial>
      <origin rpy="0 0 1.5707963267948966" xyz="-0.0354389000 -0.0033586100 0.0253408000"/>
      <mass value="1"/>
      <inertia ixx="0.0033530000" ixy="-0.0001246000" ixz="0.0000110600" iyy="0.0013570000" iyz="0.0002103000" izz="0.0041110000"/>
    </inertial>
  </link>
  
  <!-- fixed joint that connects the mount to the base of the rx 200" -->
  <joint name="actuator_base_joint" type="fixed">
    <parent link="rx200pantex/mount"/>
    <child link="rx200pantex/waist_link"/>
    <origin xyz="0 0 0.003175"/>
  </joint>
<!-- end -->
  
<!-- trossen robotics -->
  <link name="rx200pantex/waist_link">
    <visual>
      <origin rpy="0 0 -1.5707963267948966" xyz="0 0 0"/>
      <geometry>
        <mesh filename="package://data/sim/meshes/RXA-200-M-1-Base.stl" scale="0.001 0.001 0.001"/>
      </geometry>
      <material name="interbotix_black"/>
    </visual>
    <collision>
      <origin rpy="0 0 -1.5707963267948966" xyz="0 0 0"/>
      <geometry>
        <mesh filename="package://data/sim/meshes/RXA-200-M-1-Base.stl" scale="0.001 0.001 0.001"/>
      </geometry>
    </collision>
    <inertial>
      <origin rpy="0 0 1.5707963267948966" xyz="-0.0354389000 -0.0033586100 0.0253408000"/>
      <mass value="0.766135"/>
      <inertia ixx="0.0033530000" ixy="-0.0001246000" ixz="0.0000110600" iyy="0.0013570000" iyz="0.0002103000" izz="0.0041110000"/>
    </inertial>
  </link>
  <joint name="waist" type="revolute">
    <axis xyz="0 0 1"/>
    <limit effort="8" lower="-3.141582653589793" upper="3.141582653589793" velocity="3.141592653589793"/>
    <origin rpy="0 0 0" xyz="0 0 0.06566"/>
    <parent link="rx200pantex/waist_link"/>
    <child link="rx200pantex/shoulder_link"/>
    <dynamics friction="0.1"/>
  </joint>
  <link name="rx200pantex/shoulder_link">
    <visual>
      <origin rpy="0 0 -1.5707963267948966" xyz="0 0 0.0015"/>
      <geometry>
        <mesh filename="package://data/sim/meshes/RXA-200-M-2-Shoulder.stl" scale="0.001 0.001 0.001"/>
      </geometry>
      <material name="interbotix_black"/>
    </visual>
    <collision>
      <origin rpy="0 0 -1.5707963267948966" xyz="0 0 0.0015"/>
      <geometry>
        <mesh filename="package://data/sim/meshes/RXA-200-M-2-Shoulder.stl" scale="0.001 0.001 0.001"/>
      </geometry>
    </collision>
    <inertial>
      <origin rpy="0 0 1.5707963267948966" xyz="-0.0000853644 0.0000173690 0.0132005000"/>
      <mass value="0.257774"/>
      <inertia ixx="0.0002663000" ixy="0.0000000009" ixz="0.0000000511" iyy="0.0004428000" iyz="0.0000004416" izz="0.0004711000"/>
    </inertial>
  </link>
  <joint name="shoulder" type="revolute">
    <axis xyz="0 1 0"/>
    <limit effort="1000" lower="-1.8849555921538759" upper="1.9722220547535925" velocity="1"/>
    <origin rpy="0 0 0" xyz="0 0 0.03891"/>
    <parent link="rx200pantex/shoulder_link"/>
    <child link="rx200pantex/upper_arm_link"/>
    <dynamics friction="0.1"/>
  </joint>
  <link name="rx200pantex/upper_arm_link">
    <visual>
      <origin rpy="0 0 1.5707963267948966" xyz="0 0 0"/>
      <geometry>
        <mesh filename="package://data/sim/meshes/RXA-200-M-3-UA.stl" scale="0.001 0.001 0.001"/>
      </geometry>
      <material name="interbotix_black"/>
    </visual>
    <collision>
      <origin rpy="0 0 1.5707963267948966" xyz="0 0 0"/>
      <geometry>
        <mesh filename="package://data/sim/meshes/RXA-200-M-3-UA.stl" scale="0.001 0.001 0.001"/>
      </geometry>
    </collision>
    <inertial>
      <origin rpy="0 0 1.5707963267948966" xyz="0.0119513000 -0.0001169230 0.1394300000"/>
      <mass value="0.297782"/>
      <inertia ixx="0.0017100000" ixy="-0.0000009773" ixz="0.0000020936" iyy="0.0016310000" iyz="0.0002132000" izz="0.0001478000"/>
    </inertial>
  </link>
  <joint name="elbow" type="revolute">
    <axis xyz="0 1 0"/>
    <limit effort="1000" lower="-1.8849555921538759" upper="1.6231562043547265" velocity="3.141592653589793"/>
    <origin rpy="0 0 0" xyz="0.05 0 0.2"/>
    <parent link="rx200pantex/upper_arm_link"/>
    <child link="rx200pantex/forearm_link"/>
    <dynamics friction="0.1"/>
  </joint>
  <link name="rx200pantex/forearm_link">
    <visual>
      <origin rpy="0 0 1.5707963267948966" xyz="0 0 0"/>
      <geometry>
        <mesh filename="package://data/sim/meshes/RXA-200-M-4-Forearm.stl" scale="0.001 0.001 0.001"/>
      </geometry>
      <material name="interbotix_black"/>
    </visual>
    <collision>
      <origin rpy="0 0 1.5707963267948966" xyz="0 0 0"/>
      <geometry>
        <mesh filename="package://data/sim/meshes/RXA-200-M-4-Forearm.stl" scale="0.001 0.001 0.001"/>
      </geometry>
    </collision>
    <inertial>
      <origin rpy="0 0 1.5707963267948966" xyz="0.1147450000 -0.0000938376 0.0000000000"/>
      <mass value="0.258863"/>
      <inertia ixx="0.0010550000" ixy="-0.0000018286" ixz="0.0000000000" iyy="0.0000642100" iyz="0.0000000000" izz="0.0010760000"/>
    </inertial>
  </link>
  <joint name="wrist_angle" type="revolute">
    <axis xyz="0 1 0"/>
    <limit effort="1000" lower="-1.57079632679" upper="1.57079632679" velocity="3.141592653589793"/>
    <origin rpy="0 0 0" xyz="0.2 0 0"/>
    <parent link="rx200pantex/forearm_link"/>
    <child link="rx200pantex/wrist_link"/>
    <dynamics friction="0.1"/>
  </joint>
  <link name="rx200pantex/wrist_link">
    <visual>
      <origin rpy="0 0 1.5707963267948966" xyz="0 0 0"/>
      <geometry>
	  <!--> Changed wrist to proper probe assembly<-->
        <mesh filename="package://data/sim/meshes/RXA-200-M-5-PROBE_ASSEMBLY.stl" scale="0.001 0.001 0.001"/>
      </geometry>
      <material name="interbotix_black"/>
    </visual>
    <collision>
      <origin rpy="1.5707963267948966 0 1.5707963267948966" xyz="0 0 0"/>
      <geometry>
	  <!--> Changed wrist to proper probe assembly<-->
	  <!--> Also made it use a VHACD model for accurate collisions <-->
	 	<mesh filename="package://data/sim/models/modified_wrist_vhacd.obj" scale="1 1 1"/>
      </geometry>
    </collision>
    <inertial>
      <origin rpy="0 0 1.5707963267948966" xyz="0.0423600000 -0.0000104110 0.0105770000"/>
      <mass value="0.084957"/>
      <inertia ixx="0.0000308200" ixy="0.0000000191" ixz="0.0000000023" iyy="0.0000282200" iyz="0.0000025481" izz="0.0000315200"/>
    </inertial>
  </link>
  
<!-- end of interbotix provided code -->

<joint name="probe_ref_joint" type="fixed">
    <origin rpy="0 0 0" xyz="0.1475 0 0.0175"/>
    <parent link="rx200pantex/wrist_link"/>
    <child link="rx200pantex/probe_tip_ref"/>
</joint>

<link name="rx200pantex/probe_tip_ref">
    <visual>
      <origin rpy="0 0 0" xyz="0 0 0"/>
      <geometry>
        <sphere radius="0.005"/>
      </geometry>
      <material name="interbotix_black"/>
    </visual>
	
    <collision>
      <origin rpy="0 0 0" xyz="0 0 0"/>
      <geometry>
        <sphere radius="0.005"/>
      </geometry>
    </collision>
	
	 <inertial>
      <origin rpy="0 0 0" xyz="0 0 0"/>
      <mass value="1"/>
      <inertia ixx="0" ixy="0" ixz="0" iyy="0" iyz="0" izz="0"/>
    </inertial>
</link>


</robot>
