<?xml version="1.0"?>
<robot name="rx200">

  <material name="interbotix_black">
	<color rgba="0.1 0.1 0.1 1"/>
  </material>
  
  <material name="silver">
	<color rgba="0.6 0.6 0.6 1"/>
  </material>
  
  <link name="world" />  

  <joint name="world_joint" type="fixed">
    <origin rpy="0 0 0" xyz="0 0 0"/>
    <parent link="world"/>
    <child link="rx200/linear_actuator"/>
  </joint>  
  
  <link name="rx200/linear_actuator">
	<visual>
      <origin rpy="0 0 0" xyz="0 0 0"/>
      <geometry>
        <mesh filename="../Data/sim/meshes/LINEAR_ACTUATOR.stl" scale="0.001 0.001 0.001"/>
      </geometry>
      <material name="silver"/>
	</visual>
	<collision>
	  <origin rpy="0 0 0" xyz="0 0 0"/>
	  <geometry>
		<mesh filename="../Data/sim/meshes/LINEAR_ACTUATOR.stl" scale="0.001 0.001 0.001"/>
	  </geometry>
	</collision>
	<inertial>
      <origin xyz="0 0 0"/>
      <mass value="20"/>
      <inertia ixx="0.0033530000" iyy="0.0013570000" izz="0.0041110000" ixy="-0.0001246000" ixz="0.0000110600" iyz="0.0002103000" />
	</inertial>
  </link>
  
  <joint name="rail_base" type="prismatic">
    <axis xyz="0 1 0"/>
    <limit effort="8" lower="0" upper="0.325" velocity="0.05"/>
    <origin rpy="0 0 0" xyz="0 -0.125 0.1425"/>
    <parent link="rx200/linear_actuator"/>
    <child link="rx200/base_link"/>
    <dynamics friction="0.1"/>
  </joint>

  <link name="rx200/base_link">
    <visual>
      <origin rpy="0 0 0" xyz="0 0 0"/>
      <geometry>
        <mesh filename="../Data/sim/meshes/RX200_BASE.stl" scale="0.001 0.001 0.001"/>
      </geometry>
      <material name="interbotix_black"/>
    </visual>
    <collision>
      <origin rpy="0 0 0" xyz="0 0 0"/>
      <geometry>
        <mesh filename="../Data/sim/meshes/RX200_BASE.stl" scale="0.001 0.001 0.001"/>
      </geometry>
    </collision>
    <inertial>
      <origin rpy="0 0 0" xyz="-0.0354389000 -0.0033586100 0.0253408000"/>
      <mass value="0.766135" />
      <inertia ixx="0.0033530000" iyy="0.0013570000" izz="0.0041110000" ixy="-0.0001246000" ixz="0.0000110600" iyz="0.0002103000" />
    </inertial>
  </link>

  <joint name="waist" type="revolute">
    <axis xyz="0 0 1"/>
    <limit effort="8" lower="-1.57078632679" upper="1.57080632679" velocity="3.14159"/>
    <origin rpy="0 0 0" xyz="0.00625 0 0"/>
    <parent link="rx200/base_link"/>
    <child link="rx200/shoulder_link"/>
    <dynamics friction="0.1"/>
  </joint>

  <transmission name="trans_waist">
    <type>transmission_interface/SimpleTransmission</type>
    <joint name="waist">
      <hardwareInterface>hardware_interface/EffortJointInterface</hardwareInterface>
    </joint>
    <actuator name="waist_motor">
      <mechanicalReduction>1</mechanicalReduction>
    </actuator>
  </transmission>

  <link name="rx200/shoulder_link">
    <visual>
      <origin rpy="0 0 -1.57079632679" xyz="0 0 0.0015"/>
      <geometry>
        <mesh filename="../Data/sim/meshes/RX200_SHOULDER.stl" scale="0.001 0.001 0.001"/>
      </geometry>
      <material name="interbotix_black"/>
    </visual>
    <collision>
      <origin rpy="0 0 -1.57079632679" xyz="0 0 0.0015"/>
      <geometry>
        <mesh filename="../Data/sim/meshes/RX200_SHOULDER.stl" scale="0.001 0.001 0.001"/>
      </geometry>
    </collision>
    <inertial>
      <origin rpy="0 0 1.57079632679" xyz="-0.0000853644 0.0000173690 0.0132005000"/>
      <mass value="0.257774" />
      <inertia ixx="0.0002663000" iyy="0.0004428000" izz="0.0004711000" ixy="0.0000000009" ixz="0.0000000511" iyz="0.0000004416" />
    </inertial>
  </link>

  <joint name="shoulder" type="revolute">
    <axis xyz="0 1 0"/>
    <limit effort="18" lower="-1.88496" upper="1.97222" velocity="1"/>
    <origin rpy="0 0 0" xyz="0 0 0.03891"/>
    <parent link="rx200/shoulder_link"/>
    <child link="rx200/upper_arm_link"/>
    <dynamics friction="0.1"/>
  </joint>

  <transmission name="trans_shoulder">
    <type>transmission_interface/SimpleTransmission</type>
    <joint name="shoulder">
      <hardwareInterface>hardware_interface/EffortJointInterface</hardwareInterface>
    </joint>
    <actuator name="shoulder_motor">
      <mechanicalReduction>1</mechanicalReduction>
    </actuator>
  </transmission>

  <link name="rx200/upper_arm_link">
    <visual>
      <origin rpy="0 0 1.57079632679" xyz="0 0 0"/>
      <geometry>
        <mesh filename="../Data/sim/meshes/RX200_UA.stl" scale="0.001 0.001 0.001"/>
      </geometry>
      <material name="interbotix_black"/>
    </visual>
    <collision>
      <origin rpy="0 0 1.57079632679" xyz="0 0 0"/>
      <geometry>
        <mesh filename="../Data/sim/meshes/RX200_UA.stl" scale="0.001 0.001 0.001"/>
      </geometry>
    </collision>
    <inertial>
      <origin rpy="0 0 1.57079632679" xyz="0.0119513000 -0.0001169230 0.1394300000"/>
      <mass value="0.297782" />
      <inertia ixx="0.0017100000" iyy="0.0016310000" izz="0.0001478000" ixy="-0.0000009773" ixz="0.0000020936" iyz="0.0002132000" />
    </inertial>
  </link>

  <joint name="elbow" type="revolute">
    <axis xyz="0 1 0"/>
    <limit effort="13" lower="-1.88496" upper="1.62316" velocity="3.14159"/>
    <origin rpy="0 0 0" xyz="0.05 0 0.2"/>
    <parent link="rx200/upper_arm_link"/>
    <child link="rx200/forearm_link"/>
    <dynamics friction="0.1"/>
  </joint>

  <transmission name="trans_elbow">
    <type>transmission_interface/SimpleTransmission</type>
    <joint name="elbow">
      <hardwareInterface>hardware_interface/EffortJointInterface</hardwareInterface>
    </joint>
    <actuator name="elbow_motor">
      <mechanicalReduction>1</mechanicalReduction>
    </actuator>
  </transmission>

  <link name="rx200/forearm_link">
    <visual>
      <origin rpy="0 0 1.57079632679" xyz="0 0 0"/>
      <geometry>
        <mesh filename="../Data/sim/meshes/RX200_FOREARM.stl" scale="0.001 0.001 0.001"/>
      </geometry>
      <material name="interbotix_black"/>
    </visual>
    <collision>
      <origin rpy="0 0 1.57079632679" xyz="0 0 0"/>
      <geometry>
        <mesh filename="../Data/sim/meshes/RX200_FOREARM.stl" scale="0.001 0.001 0.001"/>
      </geometry>
    </collision>
    <inertial>
      <origin rpy="0 0 1.57079632679" xyz="0.1147450000 -0.0000938376 0.0000000000"/>
      <mass value="0.258863" />
      <inertia ixx="0.0010550000" iyy="0.0000642100" izz="0.0010760000" ixy="-0.0000018286" ixz="0.0000000000" iyz="0.0000000000" />
    </inertial>
  </link>

  <joint name="wrist_angle" type="revolute">
    <axis xyz="0 1 0"/>
    <limit effort="5" lower="-1.74533" upper="2.14675" velocity="3"/>
    <origin rpy="0 0 0" xyz="0.2 0 0"/>
    <parent link="rx200/forearm_link"/>
    <child link="rx200/wrist_link"/>
    <dynamics friction="0.1"/>
  </joint>

  <transmission name="trans_wrist_angle">
    <type>transmission_interface/SimpleTransmission</type>
    <joint name="wrist_angle">
      <hardwareInterface>hardware_interface/EffortJointInterface</hardwareInterface>
    </joint>
    <actuator name="wrist_angle_motor">
      <mechanicalReduction>1</mechanicalReduction>
    </actuator>
  </transmission>

  <link name="rx200/wrist_link">
    <visual>
      <origin rpy="0 0 1.57079632679" xyz="0 0 0"/>
      <geometry>
        <mesh filename="../Data/sim/meshes/RX200_PROBE_WRIST.stl" scale="0.001 0.001 0.001"/>
      </geometry>
      <material name="interbotix_black"/>
    </visual>
    <collision>
      <origin rpy="0 0 1.57079632679" xyz="0 0 0"/>
      <geometry>
        <mesh filename="../Data/sim/meshes/RX200_PROBE_WRIST.stl" scale="0.001 0.001 0.001"/>
      </geometry>
    </collision>
    <inertial>
      <origin rpy="0 0 1.57079632679" xyz="0.0423600000 -0.0000104110 0.0105770000"/>
      <mass value="0.084957" />
      <inertia ixx="0.0000308200" iyy="0.0000282200" izz="0.0000315200" ixy="0.0000000191" ixz="0.0000000023" iyz="0.0000025481" />
    </inertial>
  </link>

<joint name="probe_ref_joint" type="fixed">
    <origin rpy="0 0 0" xyz="0.18 0.01 0.017"/>
    <parent link="rx200/wrist_link"/>
    <child link="rx200/probe_tip_ref"/>
</joint>

<link name="rx200/probe_tip_ref">
    <visual>
      <origin rpy="0 0 0" xyz="0 0 0"/>
      <geometry>
        <sphere radius="0.005"/>
      </geometry>
      <material name="interbotix_black"/>
    </visual>
	
    <collision>
      <origin rpy="0 0 0" xyz="0 0 0"/>
      <geometry>
        <sphere radius="0.005"/>
      </geometry>
    </collision>
</link>

</robot>